<?xml version="1.0" ?>
<!-- =================================================================================== -->
<!-- |    This document was autogenerated by xacro from robot.urdf.xacro               | -->
<!-- |    EDITING THIS FILE BY HAND IS NOT RECOMMENDED                                 | -->
<!-- =================================================================================== -->
<robot name="lmr1">
  <!-- ==================== -->
  <!-- Constants -->
  <!-- ==================== -->
  <!-- ==================== -->
  <!-- Base Dimensions -->
  <!-- ==================== -->
  <!-- ==================== -->
  <!-- Wheel Dimensions -->
  <!-- ==================== -->
  <!-- ==================== -->
  <!-- Caster -->
  <!-- ==================== -->
  <!-- ==================== -->
  <!-- Sensors -->
  <!-- ==================== -->
  <!-- ========================================= -->
  <!-- Box inertia -->
  <!-- ========================================= -->
  <!-- ========================================= -->
  <!-- Cylinder inertia -->
  <!-- cylinder aligned with z-axis -->
  <!-- ========================================= -->
  <link name="base_link">
    <inertial>
      <origin rpy="0 0 0" xyz="0.0                      0.0                      0.0"/>
      <mass value="2.0"/>
      <inertia ixx="0.008216666666666666" ixy="0.0" ixz="0.0" iyy="0.017816666666666665" iyz="0.0" izz="0.020399999999999998"/>
    </inertial>
    <!-- ======================== -->
    <!-- Visual -->
    <!-- ======================== -->
    <visual>
      <origin rpy="0 0 0" xyz="0.0                      0.0                      0.0"/>
      <geometry>
        <mesh filename="package://lmr1_description/meshes/base.dae"/>
      </geometry>
    </visual>
    <!-- ======================== -->
    <!-- Collision -->
    <!-- ======================== -->
    <collision>
      <origin rpy="0 0 0" xyz="0.0                      0.0                      0.0"/>
      <geometry>
        <box size="0.3                            0.18                            0.13"/>
      </geometry>
    </collision>
  </link>
  <link name="caster_wheel_link">
    <!-- collision -->
    <collision>
      <origin rpy="0 0 0" xyz="0 0 0"/>
      <geometry>
        <sphere radius="0.0075"/>
      </geometry>
    </collision>
  </link>
  <joint name="caster_wheel_joint" type="fixed">
    <origin rpy="0 0 0" xyz="0.175                  0.0                  -0.0255"/>
    <parent link="base_link"/>
    <child link="caster_wheel_link"/>
  </joint>
  <!-- ======================== -->
  <!-- IMU -->
  <!-- ======================== -->
  <link name="imu_link"/>
  <joint name="imu_joint" type="fixed">
    <origin rpy="0 0 0" xyz="-0.06                  0.0                  0.06"/>
    <parent link="base_link"/>
    <child link="imu_link"/>
  </joint>
  <!-- ======================== -->
  <!-- LiDAR -->
  <!-- ======================== -->
  <link name="lidar_link"/>
  <joint name="lidar_joint" type="fixed">
    <origin rpy="0 0 0" xyz="0.04                  0.0                  0.12"/>
    <parent link="base_link"/>
    <child link="lidar_link"/>
  </joint>
  <!-- ======================== -->
  <!-- Wheel Link -->
  <!-- ======================== -->
  <link name="left_wheel_link">
    <!-- Inertial -->
    <inertial>
      <origin rpy="0 0 0" xyz="0 0 0"/>
      <mass value="0.05"/>
      <inertia ixx="1.4869791666666668e-05" ixy="0.0" ixz="0.0" iyy="1.4869791666666668e-05" iyz="0.0" izz="2.6406250000000005e-05"/>
    </inertial>
    <!-- Visual -->
    <visual>
      <origin rpy="0 -1.570796326795 0" xyz="0 0 0"/>
      <geometry>
        <mesh filename="package://lmr1_description/meshes/wheel.dae"/>
      </geometry>
    </visual>
    <!-- Collision -->
    <collision>
      <origin rpy="0 0 0" xyz="0 0 0"/>
      <geometry>
        <cylinder length="0.02" radius="0.0325"/>
      </geometry>
    </collision>
  </link>
  <!-- ======================== -->
  <!-- Wheel Joint -->
  <!-- ======================== -->
  <joint name="left_wheel_joint" type="continuous">
    <origin rpy="-1.570796326795 0 0" xyz="0 0.1 0.0"/>
    <parent link="base_link"/>
    <child link="left_wheel_link"/>
    <axis xyz="0 0 1"/>
  </joint>
  <!-- ======================== -->
  <!-- Wheel Link -->
  <!-- ======================== -->
  <link name="right_wheel_link">
    <!-- Inertial -->
    <inertial>
      <origin rpy="0 0 0" xyz="0 0 0"/>
      <mass value="0.05"/>
      <inertia ixx="1.4869791666666668e-05" ixy="0.0" ixz="0.0" iyy="1.4869791666666668e-05" iyz="0.0" izz="2.6406250000000005e-05"/>
    </inertial>
    <!-- Visual -->
    <visual>
      <origin rpy="0 -1.570796326795 0" xyz="0 0 0"/>
      <geometry>
        <mesh filename="package://lmr1_description/meshes/wheel.dae"/>
      </geometry>
    </visual>
    <!-- Collision -->
    <collision>
      <origin rpy="0 0 0" xyz="0 0 0"/>
      <geometry>
        <cylinder length="0.02" radius="0.0325"/>
      </geometry>
    </collision>
  </link>
  <!-- ======================== -->
  <!-- Wheel Joint -->
  <!-- ======================== -->
  <joint name="right_wheel_joint" type="continuous">
    <origin rpy="1.570796326795 0 0" xyz="0 -0.1 0.0"/>
    <parent link="base_link"/>
    <child link="right_wheel_link"/>
    <axis xyz="0 0 -1"/>
  </joint>
  <gazebo>
    <plugin filename="libgazebo_ros_diff_drive.so" name="diff_drive_controller">
      <!-- wheels -->
      <leftJoint>left_wheel_joint</leftJoint>
      <rightJoint>right_wheel_joint</rightJoint>
      <!-- geometry -->
      <wheelSeparation>0.2</wheelSeparation>
      <wheelDiameter>0.065</wheelDiameter>
      <!-- limits -->
      <maxWheelTorque>5</maxWheelTorque>
      <maxWheelAcceleration>10</maxWheelAcceleration>
      <!-- topics -->
      <commandTopic>cmd_vel</commandTopic>
      <odometryTopic>odom</odometryTopic>
      <!-- frames -->
      <odometryFrame>odom</odometryFrame>
      <robotBaseFrame>base_link</robotBaseFrame>
      <!-- behavior -->
      <publishWheelTF>true</publishWheelTF>
      <publishTf>true</publishTf>
      <publishWheelJointState>true</publishWheelJointState>
      <!-- update -->
      <updateRate>50</updateRate>
    </plugin>
  </gazebo>
  <gazebo reference="left_wheel_link">
    <mu1>1.0</mu1>
    <mu2>1.0</mu2>
    <kp>1000000.0</kp>
    <kd>100.0</kd>
  </gazebo>
  <gazebo reference="right_wheel_link">
    <mu1>1.0</mu1>
    <mu2>1.0</mu2>
    <kp>1000000.0</kp>
    <kd>100.0</kd>
  </gazebo>
</robot>

